<?xml version='1.0'?>

<robot name="vast_robot" xmlns:xacro="http://www.ros.org/wiki/xacro">


  <xacro:include filename="$(find ros_robotics)/urdf/vast1.gazebo" />

  <link name="base_footprint"></link>

  <joint name="robot_footprint_joint" type="fixed">
    <origin xyz="0 0 0.2" rpy="0 0 0" />
    <parent link="base_footprint" />
    <child link="base_link" />
  </joint>
  <!-- Base Link -->
  <link name="base_link">
    <visual>
      <origin xyz="0 0 0" rpy="0 0 0" />
      <geometry>
        <box size="1 1 0.15"/>
        <!--long,wide,tall-->
      </geometry>
      <material name="blue">
        <color rgba="0 0.5 1 1"/>
      </material>
    </visual>
    <!-- Base collision -->
    <collision>
	<origin xyz="0 0 0" rpy="0 0 0" />
      <geometry>
        <box size="1 1 0.15"/>
        <!--long,wide,tall-->
      </geometry>
    </collision>
    <inertial>
      <mass value="10"/>
      <inertia ixx="1.6667" ixy="0.0" ixz="0.0"
               iyy="1.6667" iyz="0.0" izz="0.8521"/>
    </inertial>

<!-- hold_box1 -->
    <visual name="hold_box1">
      <origin xyz="0 0 0.75" rpy="0 0 0" />
      <geometry>
        <box size="0.8 0.8 0.01" />
      </geometry>
      <material name="blue"/>
    </visual>
    <!-- hold box1 collision -->
    <collision>
      <origin xyz="0 0 0.75" rpy="0 0 0" />
      <geometry>
        <box size="0.8 0.8 0.01"/>
      </geometry>
    </collision>
    <inertial>
      <mass value="2"/>
      <inertia ixx="0.21333" ixy="0.0" ixz="0.0"
               iyy="0.21333" iyz="0.0" izz="0.1067"/>
    </inertial>

<!-- hold_box2 -->
    <visual name="hold_box2">
      <origin xyz="0 0 1.43" rpy="0 0 0" />
      <geometry>
        <box size="0.8 0.8 0.01" />
      </geometry>
      <material name="blue"/>
    </visual>
    <!-- hold box2 collision -->
    <collision>
      <origin xyz="0 0 1.43" rpy="0 0 0" />
      <geometry>
        <box size="0.8 0.8 0.01"/>
      </geometry>
    </collision>
    <inertial>
      <mass value="2"/>
      <inertia ixx="0.21333" ixy="0.0" ixz="0.0"
               iyy="0.21333" iyz="0.0" izz="0.1067"/>
    </inertial>
  <!-- left_bottom cylinder -->
    <visual name="left_bottom_cylinder">
      <origin xyz="0.25 -0.4 0.7" rpy="0 0 0" />
      <geometry>
        <box size="0.03 0.03 1.5" />
      </geometry>
      <material name="white">
        <color rgba="0 0 0 1"/>
      </material>
    </visual>
    <!-- left bottom cylinder collision -->
    <collision>
      <origin xyz="0.25 -0.4 0.7" rpy="0 0 0" />
      <geometry>
        <box size="0.03 0.03 1.5"/>
      </geometry>
    </collision>
    <inertial>
      <mass value="0.5"/>
      <inertia ixx="0.00" ixy="0.0" ixz="0.0"
               iyy="0.00" iyz="0.0" izz="0.00"/>
    </inertial>

<!-- right_bottom cylinder -->
    <visual name="right_bottom_cylinder">
      <origin xyz="0.25 0.4 0.7" rpy="0 0 0" />
      <geometry>
        <box size="0.03 0.03 1.5" />
      </geometry>
      <material name="white"/> 
    </visual>
    <!-- right bottom cylinder collision -->
    <collision>
      <origin xyz="0.25 0.4 0.7" rpy="0 0 0" />
      <geometry>
        <box size="0.03 0.03 1.5"/>
      </geometry>
    </collision>
    <inertial>
      <mass value="0.5"/>
      <inertia ixx="0.00" ixy="0.0" ixz="0.0"
               iyy="0.00" iyz="0.0" izz="0.00"/>
    </inertial>


<!-- between_top_cylinder -->
    <visual name="between_top_cylinder">
      <origin xyz="-0.4 0 0.7" rpy="0 0 0" />
      <geometry>
        <box size="0.03 0.03 1.5" />
      </geometry>
      <material name="white"/>
    </visual>
    <!-- between bottom cylinder collision -->
    <collision>
      <origin xyz="-0.4 0 0.7" rpy="0 0 0" />
      <geometry>
        <box size="0.03 0.03 1.5"/>
      </geometry>
    </collision>
    <inertial>
      <mass value="0.5"/>
      <inertia ixx="0.00" ixy="0.0" ixz="0.0"
               iyy="0.00" iyz="0.0" izz="0.00"/>
    </inertial>

  </link>


  <!-- left_bottom Wheel -->
 <joint name="joint_left_bottom_wheel" type="continuous">
    <parent link="base_link"/>
    <child link="left_bottom_wheel"/>
    <origin xyz="-0.25 -0.55 0" rpy="0 0 -1.570795" />
    <axis xyz="1 0 0" />
  </joint>

  <transmission name="left_bottom_wheel_trans" type="SimpleTransmission">
    <type>transmission_interface/SimpleTransmission</type>
    <actuator name="left_bottom_wheel_motor">
      <mechanicalReduction>1</mechanicalReduction>
    </actuator>
    <joint name="joint_left_bottom_wheel">
      <hardwareInterface>hardware_interface/EffortJointInterface</hardwareInterface>
    </joint>
  </transmission>

  <link name="left_bottom_wheel">
    <visual>
      <origin xyz="0 0 0" rpy="0 -1.570795 0.0" />
      <geometry>
        <cylinder length="0.1" radius="0.2" />
      </geometry>
      <material name="black">
        <color rgba="0.05 0.05 0.05 1"/>
      </material>
    </visual>
    <!-- left bottom wheel collision -->
    <collision>
      <origin xyz="0 0 0" rpy="0 -1.570795 0.0" />
      <geometry>
        <cylinder length="0.1" radius="0.2" />
      </geometry>
    </collision>
    <inertial>
      <mass value="5"/>
      <inertia ixx="0.0108" ixy="0.0" ixz="0.0"
               iyy="0.0108" iyz="0.0" izz="0.025"/>
    </inertial>


  </link>

  
  <!-- right bottom Wheel -->
  <joint name="joint_right_bottom_wheel" type="continuous">
    <parent link="base_link"/>
    <child link="right_bottom_wheel"/>
    <origin xyz="-0.25 0.55 0" rpy="0 0 -1.570795" />
    <axis xyz="1 0 0" />
  </joint> 

  <transmission name="right_bottom_wheel_trans" type="SimpleTransmission">
    <type>transmission_interface/SimpleTransmission</type>
    <actuator name="right_bottom_wheel_motor">
      <mechanicalReduction>1</mechanicalReduction>
    </actuator>
    <joint name="joint_right_bottom_wheel">
      <hardwareInterface>hardware_interface/EffortJointInterface</hardwareInterface>
    </joint>
  </transmission> 

  <link name="right_bottom_wheel">
    <visual>
      <origin xyz="0 0 0" rpy="0 -1.570795 0" />
      <geometry>
        <cylinder length="0.1" radius="0.2" />
      </geometry>
      <material name="black"/>
    </visual>
    <!-- right bottom wheel collision -->
    <collision>
      <origin xyz="0 0 0" rpy="0 -1.570795 0" />
      <geometry>
        <cylinder length="0.1" radius="0.2" />
      </geometry>
    </collision>
    <inertial>
      <mass value="5"/>
      <inertia ixx="0.0108" ixy="0.0" ixz="0.0"
               iyy="0.0108" iyz="0.0" izz="0.025"/>
    </inertial>
  </link>

  

  <!-- left_top Wheel -->
  <joint name="joint_left_top_wheel" type="continuous">
    <parent link="base_link"/>
    <child link="left_top_wheel"/>
    <origin xyz="0.25 -0.55 0" rpy="0 0 -1.570795" />
    <axis xyz="1 0 0" />
  </joint>

  <transmission name="left_top_wheel_trans" type="SimpleTransmission">
    <type>transmission_interface/SimpleTransmission</type>
    <actuator name="left_top_wheel_motor">
      <mechanicalReduction>1</mechanicalReduction>
    </actuator>
    <joint name="joint_left_top_wheel">
      <hardwareInterface>hardware_interface/EffortJointInterface</hardwareInterface>
    </joint>
  </transmission> 
  
  <link name="left_top_wheel">
    <visual>
      <origin xyz="0 0 0" rpy="0 1.570795 0" />
      <geometry>
        <cylinder length="0.1" radius="0.2" />
      </geometry>
      <material name="black"/> 
    </visual>
    <!-- left top wheel collision -->
    <collision>
      <origin xyz="0 0 0" rpy="0 1.570795 0" />
      <geometry>
        <cylinder length="0.1" radius="0.2" />
      </geometry>
    </collision>
    <inertial>
      <mass value="5"/>
      <inertia ixx="0.0108" ixy="0.0" ixz="0.0"
               iyy="0.0108" iyz="0.0" izz="0.025"/>
    </inertial>
  </link>

  
  <!-- right top Wheel -->
  <joint name="joint_right_top_wheel" type="continuous">
    <parent link="base_link"/>
    <child link="right_top_wheel"/>
    <origin xyz="0.25 0.55 0" rpy="0 0 -1.570795" />
    <axis xyz="1 0 0" />
  </joint>

  <transmission name="right_top_wheel_trans" type="SimpleTransmission">
    <type>transmission_interface/SimpleTransmission</type>
    <actuator name="right_top_wheel_motor">
      <mechanicalReduction>1</mechanicalReduction>
    </actuator>
    <joint name="joint_right_top_wheel">
      <hardwareInterface>hardware_interface/EffortJointInterface</hardwareInterface>
    </joint>
  </transmission> 

  <link name="right_top_wheel">
    <visual>
      <origin xyz="0 0 0" rpy="0 1.570795 0" />
      <geometry>
        <cylinder length="0.1" radius="0.2" />
      </geometry>
      <material name="black"/>
    </visual>

    <!-- right top wheel collision -->
    <collision>
      <origin xyz="0 0 0" rpy="0 1.570795 0" />
      <geometry>
        <cylinder length="0.1" radius="0.2" />
      </geometry>
    </collision>
    <inertial>
      <mass value="5"/>
      <inertia ixx="0.0108" ixy="0.0" ixz="0.0"
               iyy="0.0108" iyz="0.0" izz="0.025"/>
    </inertial>
  </link>

  





 <!-- Orbbec Astra RGBD Camera -->
  <joint name="astra_joint" type="fixed">
    <axis xyz="0 0 0" />
    <origin xyz="0.4 0 1.52" rpy="0 0 0"/>
    <parent link="base_link"/>
    <child link="camera_link"/>
  </joint>

  <link name="camera_link">
    <collision>
      <origin xyz="0 0 0" rpy="0 0 0"/>
      <geometry>
        <box size="0.001 0.001 0.001"/>
      </geometry>
    </collision>

    <visual>
      <origin xyz="-0.01 0 -0.03" rpy="1.5707 0 1.5707"/>
      <geometry>
        <mesh filename="package://ros_robotics/meshes/astra.dae" scale="0.002 0.002 0.002" />
      </geometry>
    </visual>

    <inertial>
      <mass value="1e-5" />
      <origin xyz="0 0 0" rpy="0 0 0"/>
      <inertia ixx="0" ixy="0" ixz="0" iyy="0" iyz="0" izz="0" />
    </inertial>
  </link>

  <joint name="camera_optical_joint" type="fixed">
    <origin xyz="0 0 0" rpy="-1.5707 0 -1.5707"/>
    <parent link="camera_link"/>
    <child link="camera_rgb_frame"/>
  </joint>

  <link name="camera_rgb_frame">
  </link>

  <joint name="camera_depth_joint" type="fixed">
    <origin xyz="0 0 0" rpy="-1.5707 0 -1.5707"/>
    <parent link="camera_link"/>
    <child link="camera_depth_frame"/>
  </joint>

  <link name="camera_depth_frame">
  </link>

  <joint name="rplidar_joint" type="fixed">
    <axis xyz="0 1 0" />
    <origin xyz="0.02 0 1.45" rpy="0 0 3.14"/>
    <parent link="base_link"/>
    <child link="laser"/>
  </joint>

  <!-- rplidar Laser -->
  <link name="laser">
    <collision>
      <origin xyz="0 0 0" rpy="1.5707 0 4.71"/>
      <geometry>
        <mesh filename="package://ros_robotics/meshes/rplidar.dae" scale="0.002 0.002 0.002" />
      </geometry>
    </collision>

    <visual>
      <origin xyz="0 0 0" rpy="1.5707 0 4.71"/>
      <geometry>
        <mesh filename="package://ros_robotics/meshes/rplidar.dae" scale="0.002 0.002 0.002" />
      </geometry>
    </visual>

    <inertial>
      <mass value="1e-5" />
      <origin xyz="0 0 0.058" rpy="1.5707 0 4.71"/>
      <inertia ixx="0" ixy="0" ixz="0" iyy="0" iyz="0" izz="0" />
    </inertial>
  </link>

</robot>
