<?xml version='1.0'?>

<robot name="vast_robot" xmlns:xacro="http://www.ros.org/wiki/xacro">


  <xacro:include filename="$(find ros_robotics)/urdf/vast1.gazebo" />

  <link name="base_footprint">
	<visual>
			  <origin xyz="0 0 0" rpy="0 0 0" />
			  <geometry>
				 <box size="0.001 0.001 0.001" />
			  </geometry>
		  </visual>
		</link>

  <joint name="robot_footprint_joint" type="fixed">
    <origin xyz="0 0 0.05" rpy="0 0 0" />
    <parent link="base_footprint" />
    <child link="base_link" />
  </joint>
  <!-- Base Link -->
  <link name="base_link">
    <visual>
      <origin xyz="0 0 0" rpy="0 0 0" />
      <geometry>
        <box size="0.4 0.4 0.05"/>
        <!--long,wide,tall-->
      </geometry>
      <material name="blue">
        <color rgba="0 0.5 1 1"/>
      </material>
    </visual>
    <!-- Base collision -->
    <collision>
	<origin xyz="0 0 0" rpy="0 0 0" />
      <geometry>
        <box size="0.4 0.4 0.05"/>
        <!--long,wide,tall-->
      </geometry>
    </collision>
    <inertial>
      <mass value="50.0"/>
      <inertia ixx="0.01" ixy="0.0" ixz="0.0"
               iyy="0.01" iyz="0.0" izz="0.001"/>
    </inertial>
  

  <visual name="left_bottom_cylinder">
      <origin xyz="0.15 -0.15 0.25" rpy="0 0 0" />
      <geometry>
        <box size="0.01 0.01 0.5" />
      </geometry>
      <material name="white">
        <color rgba="0 0 0 1"/>
      </material>
    </visual>
    <!-- left bottom cylinder collision -->

<!-- right_bottom cylinder -->
    <visual name="right_bottom_cylinder">
      <origin xyz="0.15 0.15 0.25" rpy="0 0 0" />
      <geometry>
        <box size="0.01 0.01 0.5" />
      </geometry>
      <material name="white"/> 
    </visual>

<!-- between_top_cylinder -->
    <visual name="between_top_cylinder">
      <origin xyz="-0.15 0 0.25" rpy="0 0 0" />
      <geometry>
        <box size="0.01 0.01 0.5" />
      </geometry>
      <material name="white"/>
    </visual>

  <!-- hold_box1 -->
    <visual name="hold_box1">
      <origin xyz="0 0 0.25" rpy="0 0 0" />
      <geometry>
        <box size="0.3 0.3 0.01" />
      </geometry>
      <material name="blue"/>
    </visual>
 
<!-- hold_box2 -->
    <visual name="hold_box2">
      <origin xyz="0 0 0.5" rpy="0 0 0" />
      <geometry>
        <box size="0.3 0.3 0.01" />
      </geometry>
      <material name="blue"/>
    </visual>
  </link>

  <!-- Orbbec Astra RGBD Camera -->
  <joint name="astra_joint" type="fixed">
    <axis xyz="0 0 0" />
    <origin xyz="0.15 0 0.3" rpy="0 0 0"/>
    <parent link="base_link"/>
    <child link="camera_link"/>
  </joint>

  <link name="camera_link">
    <collision>
      <origin xyz="0 0 0" rpy="0 0 0"/>
      <geometry>
        <box size="0.001 0.001 0.001"/>
      </geometry>
    </collision>

    <visual>
      <origin xyz="-0.01 0 -0.03" rpy="1.5707 0 1.5707"/>
      <geometry>
        <mesh filename="package://ros_robotics/meshes/astra.dae" scale="0.0005 0.0005 0.0005" />
      </geometry>
    </visual>

    <inertial>
      <mass value="1e-5" />
      <origin xyz="0 0 0" rpy="0 0 0"/>
      <inertia ixx="0" ixy="0" ixz="0" iyy="0" iyz="0" izz="0" />
    </inertial>
  </link>

  <joint name="camera_optical_joint" type="fixed">
    <origin xyz="0 0 0" rpy="-1.5707 0 -1.5707"/>
    <parent link="camera_link"/>
    <child link="camera_rgb_frame"/>
  </joint>

  <link name="camera_rgb_frame">
  </link>

  <joint name="camera_depth_joint" type="fixed">
    <origin xyz="0 0 0" rpy="-1.5707 0 -1.5707"/>
    <parent link="camera_link"/>
    <child link="camera_depth_frame"/>
  </joint>

  <link name="camera_depth_frame">
  </link>

  <joint name="rplidar_joint" type="fixed">
    <axis xyz="0 1 0" />
    <origin xyz="0.02 0 0.50" rpy="0 0 3.14"/>
    <parent link="base_link"/>
    <child link="laser"/>
  </joint>

  <!-- rplidar Laser -->
  <link name="laser">
    <collision>
      <origin xyz="0 0 0" rpy="1.5707 0 4.71"/>
      <geometry>
        <mesh filename="package://ros_robotics/meshes/rplidar.dae" scale="0.001 0.001 0.001" />
      </geometry>
    </collision>

    <visual>
      <origin xyz="0 0 0" rpy="1.5707 0 4.71"/>
      <geometry>
        <mesh filename="package://ros_robotics/meshes/rplidar.dae" scale="0.001 0.001 0.001" />
      </geometry>
    </visual>

    <inertial>
      <mass value="1e-5" />
      <origin xyz="0 0 0.058" rpy="1.5707 0 4.71"/>
      <inertia ixx="0" ixy="0" ixz="0" iyy="0" iyz="0" izz="0" />
    </inertial>
  </link>
  
<!-- IMU -->

<joint name="imu_sensor_joint" type="fixed">
        <axis xyz="0 0 1" />
        <origin xyz="0 0 0.5" rpy="0 0 0"/>
        <parent link="base_link"/>
        <child link="imu_sensor_link"/>
    </joint>
     
    <link name="imu_sensor_link">
        <collision>
            <origin xyz="0 0 0" rpy="0 0 0"/>
            <geometry>
                <box size="0.02 0.02 0.02"/>
            </geometry>
        </collision>
        <visual>
            <origin xyz="0 0 0" rpy="0 0 0"/>
            <geometry>
                <box size="0.02 0.02 0.02"/>
            </geometry>
            <material name="iRobot/Red"/>
        </visual>
        <inertial>
            <mass value="0.001" />
            <origin xyz="0 0 0" rpy="0 0 0"/>
            <inertia ixx="0.00000015" ixy="0" ixz="0" iyy="0.00000015" iyz="0" izz="0.00000015" />
        </inertial>
    </link>

  <!-- left_bottom Wheel -->
 <joint name="joint_left_bottom_wheel" type="continuous">
    <parent link="base_link"/>
    <child link="left_bottom_wheel"/>
    <origin xyz="0.2 -0.2 0" rpy="0 0 0.7853975" />
    <axis xyz="0 1 0" rpy="0 0 0" />
    <limit effort="100" velocity="100"/>
    <joint_properties damping="0.0" friction="0.0"/>
  </joint>

  <link name="left_bottom_wheel">
    <visual>
      <origin xyz="0 0 0" rpy="0 0 0.0" />
      <geometry>
	<mesh filename="package://ros_robotics/meshes/omni_wheel_2.dae" scale="0.6 0.6 0.6"/>

      </geometry>
			<material name="left_rim_material">

				<color rgba="0.5 0 0 1"/>

			</material>
    </visual>
    <!-- left bottom wheel collision -->
    <collision>
      <origin xyz="0 0 0" rpy="0 -1.570795 0.0" />
      <geometry>
       <mesh filename="package://ros_robotics/meshes/omni_wheel_2.dae" scale="0.6 0.6 0.6"/>
      </geometry>
    </collision>
    <inertial>
      <mass value="15"/>
      <inertia ixx="0.0001" ixy="0" ixz="0"
               iyy="0.0001" iyz="0" izz="0.0001"/>
    </inertial>
  </link>
  
  <transmission name="left_bottom_wheel_trans" type="SimpleTransmission">
    <type>transmission_interface/SimpleTransmission</type>
    <joint name="joint_left_bottom_wheel">
      <hardwareInterface>hardware_interface/VelocityJointInterface</hardwareInterface>
    </joint>
    <actuator name="left_bottom_wheel_motor">
      <mechanicalReduction>1</mechanicalReduction>
      <motorTorqueConstant>20</motorTorqueConstant>
    </actuator>   
  </transmission>
  
  <!-- right bottom Wheel -->
  <joint name="joint_right_bottom_wheel" type="continuous">
    <parent link="base_link"/>
    <child link="right_bottom_wheel"/>
    <origin xyz="0.2 0.2 0" rpy="0 0 2.3561925" />
    <axis xyz="0 1 0"  rpy="0 0 0" />
    <limit effort="100" velocity="100"/>
    <joint_properties damping="0.0" friction="0.0"/>
  </joint> 

  <transmission name="right_bottom_wheel_trans" type="SimpleTransmission">
    <type>transmission_interface/SimpleTransmission</type>
    <actuator name="right_bottom_wheel_motor">
      <mechanicalReduction>1</mechanicalReduction>
      <motorTorqueConstant>20</motorTorqueConstant>
    </actuator>
    <joint name="joint_right_bottom_wheel">
      <hardwareInterface>hardware_interface/VelocityJointInterface</hardwareInterface>
    </joint>
  </transmission> 

  <link name="right_bottom_wheel">
    <visual>
      <origin xyz="0 0 0" rpy="0 0 0.0" />
      <geometry>

				<mesh filename="package://ros_robotics/meshes/omni_wheel_2.dae" scale="0.6 0.6 0.6"/>

			</geometry>
			<material name="left_rim_material">

				<color rgba="0.3 0 0 1"/>

			</material>
    </visual>
    <!-- right bottom wheel collision -->
    <collision>
      <origin xyz="0 0 0" rpy="0 -1.570795 0" />
      <geometry>
        <mesh filename="package://ros_robotics/meshes/omni_wheel_2.dae" scale="0.6 0.6 0.6"/>
      </geometry>
    </collision>
    <inertial>
      <mass value="15"/>
      <inertia ixx="0.0001" ixy="0" ixz="0"
               iyy="0.0001" iyz="0" izz="0.0001"/>
    </inertial>
  </link>

  

  <!-- left_top Wheel -->
  <joint name="joint_left_top_wheel" type="continuous">
    <parent link="base_link"/>
    <child link="left_top_wheel"/>
    <origin xyz="-0.2 -0.2 0" rpy="0 0 -0.7853975" />
    <axis xyz="0 1 0"  rpy="0 0 0" />
    <limit effort="100" velocity="100"/>
    <joint_properties damping="0.0" friction="0.0"/>
  </joint>

  <transmission name="left_top_wheel_trans" type="SimpleTransmission">
    <type>transmission_interface/SimpleTransmission</type>
    <actuator name="left_top_wheel_motor">
      <mechanicalReduction>1</mechanicalReduction>
      <motorTorqueConstant>20</motorTorqueConstant>
    </actuator>
    <joint name="joint_left_top_wheel">
      <hardwareInterface>hardware_interface/VelocityJointInterface</hardwareInterface>
    </joint>
  </transmission> 
  
  <link name="left_top_wheel">
   <visual>
      <origin xyz="0 0 0" rpy="0 0 0.0" />
      <geometry>

				<mesh filename="package://ros_robotics/meshes/omni_wheel_2.dae" scale="0.6 0.6 0.6"/>

			</geometry>
			<material name="left_rim_material">

				<color rgba="0.3 0 0 1"/>

			</material>
    </visual>
    <!-- left top wheel collision -->
    <collision>
      <origin xyz="0 0 0" rpy="0 1.570795 0" />
      <geometry>
        <mesh filename="package://ros_robotics/meshes/omni_wheel_2.dae" scale="0.6 0.6 0.6"/>
      </geometry>
    </collision>
    <inertial>
      <mass value="15"/>
      <inertia ixx="0.0001" ixy="0" ixz="0"
               iyy="0.0001" iyz="0" izz="0.0001"/>
    </inertial>
  </link>

  
  <!-- right top Wheel -->
  <joint name="joint_right_top_wheel" type="continuous">
    <parent link="base_link"/>
    <child link="right_top_wheel"/>
    <origin xyz="-0.2 0.2 0" rpy="0 0 3.9269875" />
    <axis xyz="0 1 0"  rpy="0 0 0" />
    <limit effort="100" velocity="100"/>
    <joint_properties damping="0.0" friction="0.0"/>
  </joint>

  <transmission name="right_top_wheel_trans" type="SimpleTransmission">
    <type>transmission_interface/SimpleTransmission</type>
    <actuator name="right_top_wheel_motor">
      <mechanicalReduction>1</mechanicalReduction>
      <motorTorqueConstant>20</motorTorqueConstant>
    </actuator>
    <joint name="joint_right_top_wheel">
      <hardwareInterface>hardware_interface/VelocityJointInterface</hardwareInterface>
    </joint>
  </transmission> 

  <link name="right_top_wheel">
    <visual>
      <origin xyz="0 0 0" rpy="0 0 0.0" />
      <geometry>

				<mesh filename="package://ros_robotics/meshes/omni_wheel_2.dae" scale="0.6 0.6 0.6"/>

			</geometry>
			<material name="left_rim_material">

				<color rgba="0.3 0 0 1"/>

			</material>
    </visual>

    <!-- right top wheel collision -->
    <collision>
      <origin xyz="0 0 0" rpy="0 1.570795 0" />
      <geometry>
        <mesh filename="package://ros_robotics/meshes/omni_wheel_2.dae" scale="0.6 0.6 0.6"/>
      </geometry>
    </collision>
   <inertial>
      <mass value="15"/>
      <inertia ixx="0.0001" ixy="0" ixz="0"
               iyy="0.0001" iyz="0" izz="0.0001"/>
    </inertial>
  </link>




</robot>
